<robot name="Toaster">
    <link name="corpus">
        <visual>
            <geometry>
                <mesh filename="meshes/corpus.obj"/>
            </geometry>
        </visual>
        <collision>
            <geometry>
                <mesh filename="meshes/corpus.obj"/>
            </geometry>
        </collision>
    </link>
    <link name="lever">
        <visual>
            <geometry>
                <mesh filename="meshes/lever.obj"/>
            </geometry>
        </visual>
        <collision>
            <geometry>
                <mesh filename="meshes/lever.obj"/>
            </geometry>
        </collision>
    </link>

    <joint name="lever_joint" type="prismatic">
        <origin xyz="0.0 0.0 0.0" rpy="0.0 0.0 0.0"/>
        <parent link="corpus"/>
        <child link="lever"/>
        <axis xyz="0.0 -1.0 0.0"/>
        <limit lower="0.0" upper="0.015" effort="100.0" velocity="100.0"/>
    </joint>
</robot>