<robot name="Refrigerator">
    <link name="corpus">
        <visual>
            <geometry>
                <mesh filename="meshes/corpus.obj" scale="6.0"/>
            </geometry>
        </visual>
        <collision>
            <geometry>
                <mesh filename="meshes/corpus.obj" scale="6.0"/>
            </geometry>
        </collision>
    </link>
    <link name="door">
        <visual>
            <geometry>
                <mesh filename="meshes/door.obj" scale="6.0"/>
            </geometry>
        </visual>
        <collision>
            <geometry>
                <mesh filename="meshes/door.obj" scale="6.0"/>
            </geometry>
        </collision>
    </link>
    <link name="door_freezer">
        <visual>
            <geometry>
                <mesh filename="meshes/door_freezer.obj" scale="6.0"/>
            </geometry>
        </visual>
        <collision>
            <geometry>
                <mesh filename="meshes/door_freezer.obj" scale="6.0"/>
            </geometry>
        </collision>
    </link>


    <joint name="door_hinge" type="revolute">
        <origin xyz="0.0 0.0 0.0" rpy="0.0 0.0 0.0"/>
        <parent link="corpus"/>
        <child link="door"/>
        <axis xyz="0.0 0.0 1.0"/>
        <limit lower="0.0" upper="2.0944" effort="100.0" velocity="100.0"/>
    </joint>
    <joint name="door_freezer_hinge" type="revolute">
        <origin xyz="0.0 0.0 0.0" rpy="0.0 0.0 0.0"/>
        <parent link="corpus"/>
        <child link="door_freezer"/>
        <axis xyz="0.0 0.0 1.0"/>
        <limit lower="0.0" upper="2.0944" effort="100.0" velocity="100.0"/>
    </joint>
</robot>