<robot name="Refrigerator">
    <link name="corpus">
        <visual>
            <geometry>
                <mesh filename="meshes/corpus.obj" scale="6.0"/>
            </geometry>
        </visual>
        <collision>
            <geometry>
                <mesh filename="meshes/corpus.obj" scale="6.0"/>
            </geometry>
        </collision>
    </link>
    <link name="lid">
        <visual>
            <geometry>
                <mesh filename="meshes/lid.obj" scale="6.0"/>
            </geometry>
        </visual>
        <collision>
            <geometry>
                <mesh filename="meshes/lid.obj" scale="6.0"/>
            </geometry>
        </collision>
    </link>

    <joint name="lid_hinge" type="revolute">
        <origin xyz="0.0 0.0 0.0" rpy="0.0 -1.867 0.0"/>
        <parent link="corpus"/>
        <child link="lid"/>
        <axis xyz="0.0 1.0 0.0"/>
        <limit lower="0.0" upper="1.867" effort="100.0" velocity="100.0"/>
    </joint>
</robot>